<?xml version="1.0" ?>
<robot name="scara">
  <!-- Define material -->
  <material name="black">
    <color rgba="0.0 0.0 0.0 1.0"/>
  </material>
  <material name="blue">
    <color rgba="0.0 0.0 0.8 1.0"/>
  </material>
  <material name="green">
    <color rgba="0.0 0.8 0.0 1.0"/>
  </material>
  <material name="grey">
    <color rgba="0.2 0.2 0.2 1.0"/>
  </material>
  <material name="orange">
    <color rgba="1.0 0.4235294117647059 0.0392156862745098 1.0"/>
  </material>
  <material name="brown">
    <color rgba="0.8705882352941177 0.8117647058823529 0.7647058823529411 1.0"/>
  </material>
  <material name="red">
    <color rgba="0.8 0.0 0.0 1.0"/>
  </material>
  <material name="white">
    <color rgba="1.0 1.0 1.0 1.0"/>
  </material>
  <!-- For gazebo colors -->
  <gazebo reference="base_link">
    <material>Gazebo/Black</material>
  </gazebo>
  <gazebo reference="revolute1">
    <material>Gazebo/Red</material>
  </gazebo>
  <gazebo reference="link1">
    <material>Gazebo/Black</material>
  </gazebo>
  <gazebo reference="revolute2">
    <material>Gazebo/Red</material>
  </gazebo>
  <gazebo reference="link2">
    <material>Gazebo/Black</material>
  </gazebo>
  <gazebo reference="prismatic3">
    <material>Gazebo/Blue</material>
  </gazebo>
  <gazebo reference="link3">
    <material>Gazebo/Black</material>
  </gazebo>
  <!-- controller plugin-->
  <gazebo>
    <plugin filename="libgazebo_ros_control.so" name="gazebo_ros_control">
      <robotNamespace>/scara</robotNamespace>
      <robotSimType>gazebo_ros_control/DefaultRobotHWSim</robotSimType>
      <legacyModeNS>true</legacyModeNS>
    </plugin>
  </gazebo>
  <!-- Used for fixing robot to Gazebo 'base_link' -->
  <link name="world"/>
  <!-- Base Link -->
  <link name="base_link">
    <visual>
      <geometry>
        <box size="0.12 0.12 0.05"/>
      </geometry>
      <material name="blue"/>
      <origin xyz="0 0 0.025"/>
    </visual>
    <inertial>
      <mass value="1"/>
      <origin rpy="0 0 0" xyz="0 0 0.025"/>
      <inertia ixx="1" ixy="0" ixz="0" iyy="1" iyz="0" izz="1"/>
    </inertial>
    <collision>
      <geometry>
        <box size="0.12 0.12 0.05"/>
      </geometry>
      <material name="blue"/>
      <origin xyz="0 0 0.025"/>
    </collision>
  </link>
  <joint name="base2world" type="fixed">
    <parent link="world"/>
    <child link="base_link"/>
  </joint>
  <!-- revolute1 1 -->
  <link name="revolute1">
    <visual>
      <geometry>
        <cylinder length="0.45" radius="0.05"/>
      </geometry>
      <material name="green"/>
      <origin xyz="0 0 0.225"/>
    </visual>
    <inertial>
      <mass value="0.5"/>
      <origin rpy="0 0 0" xyz="0 0 0.05"/>
      
      v
      <inertia ixx="0.5" ixy="0" ixz="0" iyy="0.5" iyz="0" izz="0.5"/>
    </inertial>
    <collision>
      <geometry>
        <cylinder length="0.45" radius="0.05"/>
      </geometry>
      <material name="green"/>
      <origin xyz="0 0 0.225"/>
    </collision>
  </link>
  <joint name="joint1" type="fixed">
    <parent link="base_link"/>
    <child link="revolute1"/>
    <origin xyz="0 0 0.05"/>
  </joint>
  <!-- link 1 -->
  <link name="link1">
    <visual>
      <geometry>
        <box size="0.1 0.1 0.425"/>
      </geometry>
      <material name="blue"/>
      <origin rpy="0 1.571 0" xyz="0.2125 0 0"/>
    </visual>
    <inertial>
      <mass value="0.5"/>
      <origin rpy="0 0 0" xyz="0.2125 0 0"/>
      
      v
      <inertia ixx="0.5" ixy="0" ixz="0" iyy="0.5" iyz="0" izz="0.5"/>
    </inertial>
    <collision>
      <geometry>
        <box size="0.1 0.1 0.425"/>
      </geometry>
      <material name="blue"/>
      <origin rpy="0 1.571 0" xyz="0.2125 0 0"/>
    </collision>
  </link>
  <joint name="link12revolute1" type="revolute">
    <parent link="revolute1"/>
    <child link="link1"/>
    <origin xyz="0 0 0.4"/>
    <axis xyz="0 0 1"/>
    <limit effort="1000" velocity="0.1"/>
  </joint>
  <!-- revolute 2 -->
  <link name="revolute2">
    <visual>
      <geometry>
        <cylinder length="0.2" radius="0.05"/>
      </geometry>
      <material name="green"/>
      <origin rpy="0 0 0" xyz="0 0 0"/>
    </visual>
    <inertial>
      <mass value="0.5"/>
      <origin rpy="0 0 0" xyz="0 0 0"/>
      
      v
      <inertia ixx="0.5" ixy="0" ixz="0" iyy="0.5" iyz="0" izz="0.5"/>
    </inertial>
    <collision>
      <geometry>
        <cylinder length="0.2" radius="0.05"/>
      </geometry>
      <material name="green"/>
      <origin rpy="0 0 0" xyz="0 0 0"/>
    </collision>
  </link>
  <joint name="joint2" type="fixed">
    <parent link="link1"/>
    <child link="revolute2"/>
    <origin xyz="0.425 0 0.05"/>
  </joint>
  <!-- link 2 -->
  <link name="link2">
    <visual>
      <geometry>
        <box size="0.1 0.1 0.345"/>
      </geometry>
      <material name="blue"/>
      <origin rpy="0 1.571 0" xyz="0.1725 0 0"/>
    </visual>
    <inertial>
      <mass value="0.5"/>
      <origin rpy="0 0 0" xyz="0.1725 0 0"/>
      
      v
      <inertia ixx="0.5" ixy="0" ixz="0" iyy="0.5" iyz="0" izz="0.5"/>
    </inertial>
    <collision>
      <geometry>
        <box size="0.1 0.1 0.345"/>
      </geometry>
      <material name="blue"/>
      <origin rpy="0 1.571 0" xyz="0.1725 0 0"/>
    </collision>
  </link>
  <joint name="link22revolute2" type="revolute">
    <parent link="revolute2"/>
    <child link="link2"/>
    <origin xyz="0 0 0.05"/>
    <axis xyz="0 0 1"/>
    <limit effort="1000" velocity="0.1"/>
  </joint>
  <!-- prismatic 3 -->
  <link name="prismatic3">
    <visual>
      <geometry>
        <cylinder length="0.15" radius="0.07"/>
      </geometry>
      <material name="orange"/>
      <origin xyz="0 0 0"/>
    </visual>
    <inertial>
      <mass value="0.5"/>
      <origin rpy="0 0 0" xyz="0 0 0"/>
      
      v
      <inertia ixx="0.5" ixy="0" ixz="0" iyy="0.5" iyz="0" izz="0.5"/>
    </inertial>
    <collision>
      <geometry>
        <cylinder length="0.15" radius="0.07"/>
      </geometry>
      <material name="orange"/>
      <origin xyz="0 0 0"/>
    </collision>
  </link>
  <joint name="prismatic32link2" type="fixed">
    <parent link="link2"/>
    <child link="prismatic3"/>
    <origin rpy="3.14 0 0" xyz="0.345 0 0"/>
  </joint>
  <!-- link 3 -->
  <link name="link3">
    <visual>
      <geometry>
        <cylinder length="0.5" radius="0.03"/>
      </geometry>
      <material name="blue"/>
      <origin xyz="0 0 -0.25"/>
    </visual>
    <inertial>
      <mass value="0.2"/>
      <origin rpy="0 0 0" xyz="0 0 -0.25"/>
      <inertia ixx="0.2" ixy="0" ixz="0" iyy="0.2" iyz="0" izz="0.2"/>
    </inertial>
    <collision>
      <geometry>
        <cylinder length="0.5" radius="0.03"/>
      </geometry>
      <material name="blue"/>
      <origin xyz="0 0 -0.25"/>
    </collision>
  </link>
  <joint name="joint3" type="prismatic">
    <parent link="prismatic3"/>
    <child link="link3"/>
    <origin xyz="0 0 0.11"/>
    <limit effort="1000" lower="-0.00001" upper="0.3" velocity="0.1"/>
    <axis xyz="0 0 1"/>
    <!-- set friction to fight against gravity -->
    <dynamics damping="0.4" friction="5"/>
  </joint>
  <!-- Controller -->
  <transmission name="tran3">
    <type>transmission_interface/SimpleTransmission</type>
    <joint name="joint3">
      <hardwareInterface>hardware_interface/EffortJointInterface</hardwareInterface>
    </joint>
    <actuator name="motor3">
      <hardwareInterface>hardware_interface/EffortJointInterface</hardwareInterface>
      <mechanicalReduction>1</mechanicalReduction>
    </actuator>
  </transmission>
</robot>
